Workbook

Sheet R-alanine_Ligand
B2: Optimization+Frequency | C2: B972/pcseg -2 | D2: GAUSSIAN | Q2: Optimization+Frequency | R2: MP2/aug-cc-pvdz | S2: GAUSSIAN
B3: NMR | C3: B972/pcseg -2 | D3: GAUSSIAN | Q3: NMR | R3: B3LYP/pcs2 | S3: GAUSSIAN
A4: Electric Field (au) | C4: Magnetic Tensor | I4: Dipole moment | M4: Geometry Factor | Q4: Electric Field (au) | R4: Magnetic Tensor | W4: Dipole moment | AA4: Geometry Factor | AF4: https://www.theochem.ru.nl/units.html
A5: Direction | B5: magnitude | C5: (ppm) | I5: (Dybe) | M5: ppm-au | R5: (ppm) | W5: (Dybe) | AA5: ppm-au | AF5: 1 debye | AG5: 0.393456 | AH5: au
B6: 0 | D6: X | E6: Y | F6: Z | I6: X | J6: Y | K6: Z
D7: 259.3539 | E7: -9.4982 | F7: -4.9247 | G7: X | I7: -1.5363 | J7: 0.4753 | K7: -0.0316 | M7: =(D8-E7)*K9 + (E9-F8)*I9 + (F7-D9)*J9 -> -1.0461712
D8: -7.127 | E8: 262.6763 | F8: 5.7689 | G8: Y | I8: (au)
D9: 1.435 | E9: 5.4833 | F9: 262.034 | G9: Z | I9: =I7*$AG$5 -> -0.60446645 | J9: =J7*$AG$5 -> 0.18700964 | K9: =K7*$AG$5 -> -0.01243321
C11: Isotropic | D11: =AVERAGE(D7,E8,F9) -> 261.35473
C13: ACS | D13: =D7-D7 -> 0 | E13: =(E7-D8)/2 -> -1.1856 | F13: =(F7-D9)/2 -> -3.17985
E14: =E8-E8 -> 0 | F14: =(F8-E9)/2 -> 0.1428
F15: =F9-F9 -> 0
A16: X | B16: 0.001 | D16: X | E16: Y | F16: Z | I16: X | J16: Y | K16: Z
D17: 259.5158 | E17: -9.633 | F17: -5.1696 | G17: X | I17: -1.6467 | J17: 0.4838 | K17: -0.0702 | M17: =(D18-E17)*K19 + (E19-F18)*I19 + (F17-D19)*J19 -> -1.361621
D18: -7.301 | E18: 262.7213 | F18: 5.2892 | G18: Y | I18: (au)
D19: 1.1618 | E19: 5.4312 | F19: 262.1903 | G19: Z | I19: =I17*$AG$5 -> -0.647904 | J19: =J17*$AG$5 -> 0.19035401 | K19: =K17*$AG$5 -> -0.027620611
C21: Isotropic | D21: =AVERAGE(D17,E18,F19) -> 261.4758
C23: ACS | D23: =D17-D17 -> 0 | E23: =(E17-D18)/2 -> -1.166 | F23: =(F17-D19)/2 -> -3.1657
E24: =E18-E18 -> 0 | F24: =(F18-E19)/2 -> -0.071
F25: =F19-F19 -> 0
D26: X | E26: Y | F26: Z | I26: X | J26: Y | K26: Z | U26: electric field in magneto chiral model | V26: =0.015*2.99*10^8*30 -> 134550000 | W26: V/m
A27: X | B27: -0.001 | D27: 259.1977 | E27: -9.3991 | F27: -4.6715 | G27: X | I27: -1.4271 | J27: 0.4699 | K27: 0.0072 | M27: =(D28-E27)*K29 + (E29-F28)*I29 + (F27-D29)*J29 -> -0.79340756 | V27: =V26/(5.14*10^11) -> 0.00026177043
D28: -6.9544 | E28: 262.6804 | F28: 6.193 | G28: Y | I28: (au)
D29: 1.6982 | E29: 5.521 | F29: 261.8778 | G29: Z | I29: =I27*$AG$5 -> -0.56150106 | J29: =J27*$AG$5 -> 0.18488497 | K29: =K27*$AG$5 -> 0.0028328832
C31: Isotropic | D31: =AVERAGE(D27,E28,F29) -> 261.25197
C33: ACS | D33: =D27-D27 -> 0 | E33: =(E27-D28)/2 -> -1.22235 | F33: =(F27-D29)/2 -> -3.18485
E34: =E28-E28 -> 0 | F34: =(F28-E29)/2 -> 0.336
F35: =F29-F29 -> 0
A36: X | B36: 0.002 | D36: X | E36: Y | F36: Z | I36: X | J36: Y | K36: Z
D37: 259.6703 | E37: -9.77 | F37: -5.3988 | G37: X | I37: -1.7569 | J37: 0.4929 | K37: -0.1088 | M37: =(D38-E37)*K39 + (E39-F38)*I39 + (F37-D39)*J39 -> -1.7151587
D38: -7.4809 | E38: 262.8108 | F38: 4.7945 | G38: Y | I38: (au)
D39: 0.8854 | E39: 5.3709 | F39: 262.3094 | G39: Z | I39: =I37*$AG$5 -> -0.69126285 | J39: =J37*$AG$5 -> 0.19393446 | K39: =K37*$AG$5 -> -0.042808013
C41: Isotropic | D41: =AVERAGE(D37,E38,F39) -> 261.59683
C43: ACS | D43: =D37-D37 -> 0 | E43: =(E37-D38)/2 -> -1.14455 | F43: =(F37-D39)/2 -> -3.1421
E44: =E38-E38 -> 0 | F44: =(F38-E39)/2 -> -0.2882
F45: =F39-F39 -> 0
A46: X | B46: -0.002 | D46: X | E46: Y | F46: Z | I46: X | J46: Y | K46: Z
D47: 259.0271 | E47: -9.3113 | F47: -4.396 | G47: X | I47: -1.3176 | J47: 0.4665 | K47: 0.0471 | M47: =(D48-E47)*K49 + (E49-F48)*I49 + (F47-D49)*J49 -> -0.57810241
D48: -6.7819 | E48: 262.7214 | F48: 6.5951 | G48: Y | I48: (au)
D49: 1.9642 | E49: 5.5488 | F49: 261.6766 | G49: Z | I49: =I47*$AG$5 -> -0.51841763 | J49: =J47*$AG$5 -> 0.18354722 | K49: =K47*$AG$5 -> 0.018531778
...

Sheet S-alanine_Ligand
AF1: Reference
C2: B972/pcseg -2 | E2: GAUSSIAN | Q2: Optimization | R2: MP2/aug-cc-PVDZ | S2: GAUSSIAN | AF2: https://www.nature.com/articles/s41598-018-27110-z
B3: NMR | C3: B972/pcseg -2 | E3: GAUSSIAN | P3: NMR | Q3: NMR | R3: B3LYP/pcs2 | S3: GAUSSIAN
A4: Electric Field (au) | C4: Magnetic Tensor | I4: Dipole moment | M4: Geometry Factor | P4: Electric Field (au) | Q4: Magnetic Tensor | V4: Dipole moment | Z4: Geometry Factor
A5: Direction | B5: Value | C5: (ppm) | I5: (Dybe) | M5: ppm-au | Q5: (ppm) | V5: (Dybe) | Z5: ppm-au
B6: 0 | D6: X | E6: Y | F6: Z | I6: X | J6: Y | K6: Z | P6: 0 | Q6: X | R6: Y | S6: Z | V6: X | W6: Y | X6: Z
D7: 259.3482 | E7: 9.5012 | F7: 4.9253 | G7: X | I7: 1.5362 | J7: 0.476 | K7: -0.0309 | M7: =(D8-E7)*K9 + (E9-F8)*I9 + (F7-D9)*J9 -> 1.0528333 | Q7: 291.911 | R7: -1.1899 | S7: 0.9946 | T7: X | V7: -0.2724 | W7: 0.6808 | X7: 1.555 | Z7: =(Q8-R7)*X9 + (R9-S8)*V9 + (S7-Q9)*W9 -> 5.1474013
D8: 7.1171 | E8: 262.6748 | F8: 5.7608 | G8: Y | I8: (au) | Q8: 6.6918 | R8: 282.4162 | S8: 5.2301 | T8: Y | V8: (au)
D9: -1.4361 | E9: 5.4836 | F9: 262.0468 | G9: Z | I9: =I7*$AG$17 -> 0.60442711 | J9: =J7*$AG$17 -> 0.18728506 | K9: =K7*$AG$17 -> -0.01215779 | Q9: -3.7666 | R9: 14.0955 | S9: 254.2912 | T9: Z | V9: =V7*$AG$17 -> -0.10717741 | W9: =W7*$AG$17 -> 0.26786484 | X9: =X7*$AG$17 -> 0.61182408
C11: Isotropic | D11: =AVERAGE(D7,E8,F9) -> 261.3566
C12: ACS | D12: =D7-D7 -> 0 | E12: =(E7-D8)/2 -> 1.19205 | F12: =(F7-D9)/2 -> 3.1807
E13: =E8-E8 -> 0 | F13: =(F8-E9)/2 -> 0.1386
F14: =F9-F9 -> 0
A15: X | B15: 0.001 | D15: X | E15: Y | F15: Z | I15: X | J15: Y | K15: Z
D16: 259.1994 | E16: 9.4035 | F16: 4.6779 | G16: X | I16: 1.4272 | J16: 0.4696 | K16: 0.0066 | M16: =(D17-E16)*K18 + (E18-F17)*I18 + (F16-D18)*J18 -> 0.7949874 | AF16: https://www.theochem.ru.nl/units.html
D17: 6.9609 | E17: 262.6774 | F17: 6.1897 | G17: Y | I17: (au) | AF17: 1 debye | AG17: 0.393456 | AH17: au
D18: -1.6929 | E18: 5.5205 | F18: 261.8757 | G18: Z | I18: =I16*$AG$17 -> 0.5615404 | J18: =J16*$AG$17 -> 0.18476694 | K18: =K16*$AG$17 -> 0.0025968096
C20: Isotropic | D20: =AVERAGE(D16,E17,F18) -> 261.25083
C21: ACS | D21: =D16-D16 -> 0 | E21: =(E16-D17)/2 -> 1.2213 | F21: =(F16-D18)/2 -> 3.1854
E22: =E17-E17 -> 0 | F22: =(F17-E18)/2 -> 0.3346
F23: =F18-F18 -> 0
A24: X | B24: -0.001 | D24: X | E24: Y | F24: Z | I24: X | J24: Y | K24: Z
D25: 259.5084 | E25: 9.6231 | F25: 5.172 | G25: X | I25: 1.6463 | J25: 0.4835 | K25: -0.0703 | M25: =(D26-E25)*K27 + (E27-F26)*I27 + (F25-D27)*J27 -> 1.3601897
D26: 7.2989 | E26: 262.7184 | F26: 5.289 | G26: Y | I26: (au)
D27: -1.161 | E27: 5.4297 | F27: 262.189 | G27: Z | I27: =I25*$AG$17 -> 0.64774661 | J27: =J25*$AG$17 -> 0.19023598 | K27: =K25*$AG$17 -> -0.027659957
C29: Isotropic | D29: =AVERAGE(D25,E26,F27) -> 261.47193
C30: ACS | D30: =D25-D25 -> 0 | E30: =(E25-D26)/2 -> 1.1621 | F30: =(F25-D27)/2 -> 3.1665
E31: =E26-E26 -> 0 | F31: =(F26-E27)/2 -> -0.07035
F32: =F27-F27 -> 0
A33: X | B33: 0.002 | D33: X | E33: Y | F33: Z | I33: X | J33: Y | K33: Z
D34: 259.0336 | E34: 9.3098 | F34: 4.3871 | G34: X | I34: 1.3173 | J34: 0.4663 | K34: 0.0473 | M34: =(D35-E34)*K36 + (E36-F35)*I36 + (F34-D36)*J36 -> 0.57491108
D35: 6.7823 | E35: 262.7273 | F35: 6.6023 | G35: Y | I35: (au)
D36: -1.9708 | E36: 5.5517 | F36: 261.678 | G36: Z | I36: =I34*$AG$17 -> 0.51829959 | J36: =J34*$AG$17 -> 0.18346853 | K36: =K34*$AG$17 -> 0.018610469
C38: Isotropic | D38: =AVERAGE(D34,E35,F36) -> 261.1463
C39: ACS | D39: =D34-D34 -> 0 | E39: =(E34-D35)/2 -> 1.26375 | F39: =(F34-D36)/2 -> 3.17895
E40: =E35-E35 -> 0 | F40: =(F35-E36)/2 -> 0.5253
F41: =F36-F36 -> 0
A42: X | B42: -0.002 | D42: X | E42: Y | F42: Z | I42: X | J42: Y | K42: Z
D43: 259.671 | E43: 9.7717 | F43: 5.3984 | G43: X | I43: 1.7569 | J43: 0.4928 | K43: -0.1088 | M43: =(D44-E43)*K45 + (E45-F44)*I45 + (F43-D45)*J45 -> 1.714557
D44: 7.4819 | E44: 262.8106 | F44: 4.7951 | G44: Y | I44: (au)
...

Sheet Glycine_Ligand
AD1: 1 debye | AE1: 0.393456 | AF1: au
B2: Optimization+Frequency | D2: B972/pcseg -2 | F2: GAUSSIAN | P2: Optimization+Frequency | Q2: MP2/au-cc-pvdz | S2: GAUSSIAN
B3: NMR | D3: B972/pcseg -2 | F3: GAUSSIAN | P3: NMR | Q3: B3LYP/pcs -2 | S3: GAUSSIAN
A4: Electric Field (au) | D4: Magnetic Tensor | I4: Dipole moment | P4: Electric Field (au) | Q4: Magnetic Tensor | V4: Dipole moment | Z4: Geometry Factor
A5: Direction | B5: Value | D5: (ppm) | I5: (Dybe) | Q5: (ppm) | V5: (Dybe) | Z5: ppm-au
B6: 0 | D6: X | E6: Y | F6: Z | I6: X | J6: Y | K6: Z | P6: 0 | Q6: X | R6: Y | S6: Z | V6: X | W6: Y | X6: Z
D7: 269.0778 | E7: 0.6108 | F7: 0.0585 | G7: X | I7: 1.5839 | J7: 0.2372 | K7: -0.0103 | Q7: 291.9269 | R7: -8.6151 | S7: -4.0902 | T7: X | V7: -0.4636 | W7: -0.7583 | X7: 1.4902 | Z7: =(Q8-R7)*X9 + (R9-S8)*V9 + (S7-Q9)*W9 -> -3.7849543
D8: -3.0852 | E8: 259.4131 | F8: 0.1001 | G8: Y | I8: (au) | Q8: -11.4615 | R8: 293.2407 | S8: 0.19 | T8: Y | V8: (au)
D9: 0.0978 | E9: 0.0384 | F9: 273.6288 | G9: Z | I9: =I7*$AE$1 -> 0.62319496 | J9: =J7*$AE$1 -> 0.093327763 | K9: =K7*$AE$1 -> -0.0040525968 | Q9: -12.4066 | R9: -1.8123 | S9: 261.1123 | T9: Z | V9: =V7*$AE$1 -> -0.1824062 | W9: =W7*$AE$1 -> -0.29835768 | X9: =X7*$AE$1 -> 0.58632813
C11: Isotropic | D11: =AVERAGE(D7,E8,F9) -> 267.37323
A12: x | B12: 0.001 | D12: X | E12: Y | F12: Z | I12: X | J12: Y | K12: Z
D13: 268.992 | E13: 0.7631 | F13: 0.0519 | G13: X | I13: 1.4934 | J13: 0.2446 | K13: -0.0098
D14: -3.2374 | E14: 259.5625 | F14: 0.107 | G14: Y | I14: (au)
D15: 0.0816 | E15: 0.0478 | F15: 273.7094 | G15: Z | I15: =I13*$AE$1 -> 0.58758719 | J15: =J13*$AE$1 -> 0.096239338 | K15: =K13*$AE$1 -> -0.0038558688
C17: Isotropic | D17: =AVERAGE(D13,E14,F15) -> 267.4213
A18: X | B18: -0.001 | D18: X | E18: Y | F18: Z | I18: X | J18: Y | K18: Z
D19: 269.0512 | E19: 0.5539 | F19: 0.0478 | G19: X | I19: 1.6762 | J19: 0.2287 | K19: -0.009
D20: -2.8679 | E20: 259.3014 | F20: 0.1051 | G20: Y | I20: (au)
D21: 0.0737 | E21: 0.0392 | F21: 273.6096 | G21: Z | I21: =I19*$AE$1 -> 0.65951095 | J21: =J19*$AE$1 -> 0.089983387 | K21: =K19*$AE$1 -> -0.003541104
C23: Isotropic | D23: =AVERAGE(D19,E20,F21) -> 267.32073
A30: X | B30: 0.002 | D30: X | E30: Y | F30: Z | I30: X | J30: Y | K30: Z
D31: 268.9513 | E31: 0.8913 | F31: 0.04 | G31: X | I31: 1.4017 | J31: 0.2526 | K31: -0.0082
D32: -3.4159 | E32: 259.732 | F32: 0.0818 | G32: Y | I32: (au)
D33: 0.0712 | E33: 0.0398 | F33: 273.8044 | G33: Z | I33: =I31*$AE$1 -> 0.55150728 | J33: =J31*$AE$1 -> 0.099386986 | K33: =K31*$AE$1 -> -0.0032263392
C35: Isotropic | D35: =AVERAGE(D31,E32,F33) -> 267.4959
A36: X | B36: -0.002 | D36: X | E36: Y | F36: Z | I36: X | J36: Y | K36: Z
D37: 269.0788 | E37: 0.4492 | F37: 0.0511 | G37: X | I37: 1.7666 | J37: 0.2208 | K37: -0.0096
D38: -2.6857 | E38: 259.1605 | F38: 0.1153 | G38: Y | I38: (au)
D39: 0.0778 | E39: 0.0395 | F39: 273.5587 | G39: Z | I39: =I37*$AE$1 -> 0.69507937 | J39: =J37*$AE$1 -> 0.086875085 | K39: =K37*$AE$1 -> -0.0037771776
C41: Isotropic | D41: =AVERAGE(D37,E38,F39) -> 267.266
A42: Y | B42: 0.001 | D42: X | E42: Y | F42: Z | I42: X | J42: Y | K42: Z
D43: 268.8942 | E43: 0.6701 | F43: 0.0469 | G43: X | I43: 1.5937 | J43: 0.1765 | K43: -0.0098
D44: -2.9196 | E44: 259.1455 | F44: 0.11 | G44: Y | I44: (au)
D45: 0.0803 | E45: 0.0463 | F45: 273.5013 | G45: Z | I45: =I43*$AE$1 -> 0.62705083 | J45: =J43*$AE$1 -> 0.069444984 | K45: =K43*$AE$1 -> -0.0038558688
C47: Isotropic | D47: =AVERAGE(D43,E44,F45) -> 267.18033
A48: Y | B48: -0.001 | D48: X | E48: Y | F48: Z | I48: X | J48: Y | K48: Z
D49: 269.1613 | E49: 0.6241 | F49: 0.0426 | G49: X | I49: 1.5761 | J49: 0.297 | K49: -0.0077
D50: -3.1942 | E50: 259.6756 | F50: 0.0837 | G50: Y | I50: (au)
D51: 0.0667 | E51: 0.0329 | F51: 273.7755 | G51: Z | I51: =I49*$AE$1 -> 0.620126 | J51: =J49*$AE$1 -> 0.11685643 | K51: =K49*$AE$1 -> -0.0030296112
C53: Isotropic | D53: =AVERAGE(D49,E50,F51) -> 267.53747
...

Sheet Isotropic Change_X
A1: Electric_Field | B1: R_Alanine | C1: S_Alanine | D1: Difference | E1: Glycine
A2: 0 | B2: 261.3547 | C2: 261.3566 | D2: =ABS(B2-C2) -> 0.0019 | E2: 267.3732
A3: 0.001 | B3: 261.4758 | C3: 261.2508 | D3: =ABS(B3-C3) -> 0.225 | E3: 267.4213
A4: -0.001 | B4: 261.252 | C4: 261.4719 | D4: =ABS(B4-C4) -> 0.2199 | E4: 267.3207
A5: 0.002 | B5: 261.5968 | C5: 261.1463 | D5: =ABS(B5-C5) -> 0.4505 | E5: 267.4959 | F5: =E5-E6 -> 0.2299 | L5: ='Isotropic Change_Y'!E6-'Isotropic Change_Y'!E5 -> 0.7372
A6: -0.002 | B6: 261.1417 | C6: 261.597 | D6: =ABS(B6-C6) -> 0.4553 | E6: 267.266

Sheet Isotropic Change_Y
A1: Electric_Field | B1: R_Alanine | C1: S_Alanine | D1: Difference | E1: Glycine
A2: 0 | B2: 261.3547 | C2: 261.3566 | D2: =ABS(B2-C2) -> 0.0019 | E2: 267.3732
A3: 0.001 | B3: 261.4971 | C3: 261.4914 | D3: =ABS(B3-C3) -> 0.0057 | E3: 267.1804
A4: -0.001 | B4: 261.1761 | C4: 261.184 | D4: =ABS(B4-C4) -> 0.0079 | E4: 267.5375
A5: 0.002 | B5: 261.6012 | C5: 261.6142 | D5: =ABS(B5-C5) -> 0.013 | E5: 266.9919
A6: -0.002 | B6: 260.9401 | C6: 260.9297 | D6: =ABS(B6-C6) -> 0.0104 | E6: 267.7291

Sheet Geometry factor
A1: X direction | H1: Y Direction
A2: Electric Field | B2: Geometry Factor | H2: Electric Field | I2: Geometry Factor
A3: 0 | B3: ='S-alanine_Ligand'!M7 -> 1.0528333 | H3: 0 | I3: =B3 -> 1.0528333
A4: 0.001 | B4: ='S-alanine_Ligand'!M16 -> 0.7949874 | H4: 0.001 | I4: ='S-alanine_Ligand'!M52 -> 0.80166533
A5: -0.001 | B5: ='S-alanine_Ligand'!M25 -> 1.3601897 | H5: -0.001 | I5: ='S-alanine_Ligand'!M61 -> 1.2479207
A6: 0.002 | B6: ='S-alanine_Ligand'!M34 -> 0.57491108 | H6: 0.002 | I6: ='S-alanine_Ligand'!M70 -> 0.47790298
A7: -0.002 | B7: ='S-alanine_Ligand'!M43 -> 1.714557 | H7: -0.002 | I7: ='S-alanine_Ligand'!M79 -> 1.2639714
